<?xml version="1.0"?>
<robot xmlns:xacro="http://www.ros.org/wiki/xacro">

  <xacro:macro name="qube" params="">

    <!-- Svart kube (base) -->
    <link name="base_link">
      <visual>
        <geometry>
          <box size="0.1 0.1 0.1"/>
        </geometry>
        <origin xyz="0 0 0.05"/>
        <material name="black">
          <color rgba="0 0 0 1"/>
        </material>
      </visual>
    </link>

    <!-- Rød disk oppå boksen -->
    <link name="disk_link">
      <visual>
        <geometry>
          <cylinder radius="0.05" length="0.01"/>
        </geometry>
        <origin xyz="0 0 0"/> 
        <material name="red">
          <color rgba="1 0 0 1"/>
        </material>
      </visual>
    </link>

    <!-- Hvit viser oppå disken -->
    <link name="disk_pointer">
      <visual>
        <geometry>
          <box size="0.05 0.005 0.002"/>
        </geometry>
        <origin xyz="0.025 0 0.005"/>
        <material name="white">
          <color rgba="1 1 1 1"/>
        </material>
      </visual>
    </link>

    <!-- Joint: boks → disk -->
    <joint name="motor_joint" type="revolute">
      <parent link="base_link"/>
      <child link="disk_link"/>
      <origin xyz="0 0 0.1"/> <!-- Topp av kube -->
      <axis xyz="0 0 1"/>
      <limit effort="1.0" velocity="10.0" lower="-6.28" upper="6.28"/>
    </joint>

    <!-- Joint: disk → viser -->
    <joint name="indicator_joint" type="fixed">
      <parent link="disk_link"/>
      <child link="disk_pointer"/>
      <origin xyz="0 0 0"/>
    </joint>

  </xacro:macro>

</robot>